Workbook

Sheet Languages Overview
A1: Priority | C1: Language | D1: 1 | E1: 2 | F1: 3a | G1: 3b | H1: 3c | I1: 4
B2: LATĪNUM | C2: LAT | D2: ='001 B-'!B10 | E2: ='002 B-'!B10 | F2: ='003 T-'!B10 | G2: ='003 T-'!B10
A3: * | B3: português europeu | C3: Portuguese | D3: ='001 B-'!C10 | E3: ='002 B-'!C10 | F3: ='003 T-'!C10 | G3: ='003 T-'!C10
B4: português brasileiro | C4: Brazilian Portuguese | D4: ='001 B-'!D10 | E4: ='002 B-'!D10 | F4: ='003 T-'!D10 | G4: ='003 T-'!E10
A5: * | B5: galego | C5: Galician | D5: ='001 B-'!E10 | E5: ='002 B-'!E10 | F5: ='003 T-'!E10 | G5: ='003 T-'!F10
B6: asturlleonés | C6: Astur-Leonese | D6: ='001 B-'!F10 | E6: ='002 B-'!F10 | F6: ='003 T-'!F10 | G6: ='003 T-'!G10
A7: * | B7: castellano | C7: Castilian Spanish | D7: ='001 B-'!G10 | E7: ='002 B-'!10 | F7: ='003 T-'!10
B8: andaluz | C8: Andalusian Spanish | D8: ='001 B-'!H10 | E8: ='002 B-'!10 | F8: ='003 T-'!10
B9: español de América | C9: American Spanish | D9: ='001 B-'!I10 | E9: ='002 B-'!10 | F9: ='003 T-'!10
B10: aragonés | C10: Aragonese | D10: ='001 B-'!J10 | E10: ='002 B-'!10 | F10: ='003 T-'!10
A11: * | B11: català | C11: Catalan | D11: ='001 B-'!K10 | E11: ='002 B-'!10 | F11: ='003 T-'!10
B12: valencià | C12: Valencian | D12: ='001 B-'!L10 | E12: ='002 B-'!10 | F12: ='003 T-'!10
B13: balear | C13: Balearic | D13: ='001 B-'!M10 | E13: ='002 B-'!10 | F13: ='003 T-'!10
A14: * | B14: occitan | C14: Occitan | D14: ='001 B-'!N10 | E14: ='002 B-'!10 | F14: ='003 T-'!10
B15: gascon | C15: Gascon | D15: ='001 B-'!O10 | E15: ='002 B-'!10 | F15: ='003 T-'!10
B16: walon | C16: Walloon | D16: ='001 B-'!P10 | E16: ='002 B-'!10 | F16: ='003 T-'!10
A17: * | B17: français européen | C17: French | D17: ='001 B-'!Q10 | E17: ='002 B-'!10 | F17: ='003 T-'!10
B18: français québécois | C18: Québécois French | D18: ='001 B-'!R10 | E18: ='002 B-'!10 | F18: ='003 T-'!10
A19: * | B19: arpetan | C19: Arpitan | D19: ='001 B-'!S10 | E19: ='002 B-'!10 | F19: ='003 T-'!10
B20: lìgure | C20: Ligurian | D20: ='001 B-'!T10 | E20: ='002 B-'!10 | F20: ='003 T-'!10
A21: * | B21: lombard | C21: Lombard | D21: ='001 B-'!U10 | E21: ='002 B-'!10 | F21: ='003 T-'!10
B22: rumantsch | C22: Romansh | D22: ='001 B-'!V10 | E22: ='002 B-'!10 | F22: ='003 T-'!10
B23: furlan | C23: Friulian | D23: ='001 B-'!W10 | E23: ='002 B-'!10 | F23: ='003 T-'!10
B24: sardu logudoresu | C24: Logudorese Sardinian | D24: ='001 B-'!X10 | E24: ='002 B-'!10 | F24: ='003 T-'!10
A25: * | B25: sardu campidanesu | C25: Campidanese Sardinian | D25: ='001 B-'!Y10 | E25: ='002 B-'!10 | F25: ='003 T-'!10
B26: corsu | C26: Corsican | D26: ='001 B-'!Z10 | E26: ='002 B-'!10 | F26: ='003 T-'!10
A27: * | B27: italiano | C27: Italian | D27: ='001 B-'!AA10 | E27: ='002 B-'!10 | F27: ='003 T-'!10
B28: abbruzzese | C28: Abruzzese | D28: ='001 B-'!AB10 | E28: ='002 B-'!10 | F28: ='003 T-'!10
A29: * | B29: campane-molisane | C29: Campano-Molisan | D29: ='001 B-'!AC10 | E29: ='002 B-'!10 | F29: ='003 T-'!10
B30: pugghiese | C30: Pugliese | D30: ='001 B-'!AD10 | E30: ='002 B-'!10 | F30: ='003 T-'!10
A31: * | B31: sicilianu | C31: Sicilian | D31: ='001 B-'!AE10 | E31: ='002 B-'!10 | F31: ='003 T-'!10
A32: * | B32: vèneto | C32: Venetan | D32: ='001 B-'!AF10 | E32: ='002 B-'!10 | F32: ='003 T-'!10
A33: * | B33: armãneashti | C33: Aromanian | D33: ='001 B-'!AG10 | E33: ='002 B-'!10 | F33: ='003 T-'!10
A34: * | B34: română | C34: Romanian | D34: ='001 B-'!AH10 | E34: ='002 B-'!10 | F34: ='003 T-'!10

Sheet 001 B-
A1: A - Consonantism | D1: 1. Initial Position | I1: 1.1 Simple consonants
A3: Number | B3: 1 | F3: Latin Reference Words
A4: Treatment | B4: B- | F4: BASSU, BĀSIU, BŎVE, BOLĒTU, BŬCCA, BŬXU
A5: Environment | B5: #_{a,O}
A7: Languages | B7: LAT | C7: EU POR | D7: BR POR | E7: GAL | F7: ASL | G7: CAS ESP | H7: AND ESP | I7: AMR ESP | J7: ARG | K7: CAT | L7: VAL | M7: BAL | N7: OCC | O7: GAS OCC | P7: EU FRA | Q7: QBC FRA | R7: WAL | S7: ARP | T7: LIG | U7: LMO | V7: RMH | W7: FUR | X7: LOG SRD | Y7: CPN SRD | Z7: COR | AA7: ITA | AB7: ABR | AC7: CAM | AD7: PGL | AE7: SCN | AF7: VEN | AG7: ARO | AH7: ROM
A8: Grapheme | B8: B | C8: b | D8: b | E8: b | F8: b | G8: b | H8: b | I8: b | J8: b | K8: b | L8: b | M8: b | N8: b | O8: b | P8: b | Q8: b | R8: b | S8: b | T8: b | U8: b | V8: b | W8: b | X8: b (b) | Y8: b | Z8: b | AA8: b | AB8: v? | AC8: v | AD8: v? | AE8: v | AF8: b | AG8: b | AH8: b
A9: IPA | B9: b | C9: b | D9: b | E9: b | F9: b | G9: b | H9: b | I9: b | J9: b | K9: b | L9: b | M9: b | N9: b | O9: b | P9: b | Q9: b | R9: b | S9: b | T9: b | U9: b | V9: b | W9: b | X9: b (v) | Y9: b | Z9: b | AA9: b | AC9: v | AE9: v | AF9: b | AG9: b | AH9: b
A10: IPA key | B10: 2 | C10: 2 | D10: 2 | E10: 2 | F10: 2 | G10: 2 | H10: 2 | I10: 2 | J10: 2 | K10: 2 | L10: 2 | M10: 2 | N10: 2 | O10: 2 | P10: 2 | Q10: 2 | R10: 2 | S10: 2 | T10: 2 | U10: 2 | V10: 2 | W10: 2 | X10: 273 | Y10: 2 | Z10: 2 | AA10: 2 | AC10: 43 | AE10: 43 | AF10: 2 | AG10: 2 | AH10: 2
A11: Consonantal +/− | B11: + | C11: + | D11: + | E11: + | F11: + | G11: + | H11: + | I11: + | J11: + | K11: + | L11: + | M11: + | N11: + | O11: + | P11: + | Q11: + | R11: + | S11: + | T11: + | U11: + | V11: + | W11: + | X11: + | Y11: + | Z11: + | AA11: + | AC11: + | AE11: + | AF11: + | AG11: + | AH11: +
A12: Voice +/− | B12: + | C12: + | D12: + | E12: + | F12: + | G12: + | H12: + | I12: + | J12: + | K12: + | L12: + | M12: + | N12: + | O12: + | P12: + | Q12: + | R12: + | S12: + | T12: + | U12: + | V12: + | W12: + | X12: + | Y12: + | Z12: + | AA12: + | AC12: + | AE12: + | AF12: + | AG12: + | AH12: +
A13: Sibilant +/− | B13: − | C13: − | D13: − | E13: − | F13: − | G13: − | H13: − | I13: − | J13: − | K13: − | L13: − | M13: − | N13: − | O13: − | P13: − | Q13: − | R13: − | S13: − | T13: − | U13: − | V13: − | W13: − | X13: − | Y13: − | Z13: − | AA13: − | AC13: − | AE13: − | AF13: − | AG13: − | AH13: −
A14: Lateral +/− | B14: − | C14: − | D14: − | E14: − | F14: − | G14: − | H14: − | I14: − | J14: − | K14: − | L14: − | M14: − | N14: − | O14: − | P14: − | Q14: − | R14: − | S14: − | T14: − | U14: − | V14: − | W14: − | X14: − | Y14: − | Z14: − | AA14: − | AC14: − | AE14: − | AF14: − | AG14: − | AH14: −
A15: Place of articulation | B15: B | C15: B | D15: B | E15: B | F15: B | G15: B | H15: B | I15: B | J15: B | K15: B | L15: B | M15: B | N15: B | O15: B | P15: B | Q15: B | R15: B | S15: B | T15: B | U15: B | V15: B | W15: B | X15: B | Y15: B | Z15: B | AA15: B | AC15: B | AE15: B | AF15: B | AG15: B | AH15: B
A16: Place value | B16: 3 | C16: 3 | D16: 3 | E16: 3 | F16: 3 | G16: 3 | H16: 3 | I16: 3 | J16: 3 | K16: 3 | L16: 3 | M16: 3 | N16: 3 | O16: 3 | P16: 3 | Q16: 3 | R16: 3 | S16: 3 | T16: 3 | U16: 3 | V16: 3 | W16: 3 | X16: =AVERAGE(3,3,2.5) | Y16: 3 | Z16: 3 | AA16: 3 | AC16: 2.5 | AE16: 2.5 | AF16: 3 | AG16: 3 | AH16: 3
A17: Manner of articulation | B17: P | C17: P | D17: P | E17: P | F17: P | G17: P | H17: P | I17: P | J17: P | K17: P | L17: P | M17: P | N17: P | O17: P | P17: P | Q17: P | R17: P | S17: P | T17: P | U17: P | V17: P | W17: P | X17: P (F) | Y17: P | Z17: P | AA17: P | AC17: F | AE17: F | AF17: P | AG17: P | AH17: P
A18: Sonority value | B18: 4 | C18: 4 | D18: 4 | E18: 4 | F18: 4 | G18: 4 | H18: 4 | I18: 4 | J18: 4 | K18: 4 | L18: 4 | M18: 4 | N18: 4 | O18: 4 | P18: 4 | Q18: 4 | R18: 4 | S18: 4 | T18: 4 | U18: 4 | V18: 4 | W18: 4 | X18: =AVERAGE(4,4,2) | Y18: 4 | Z18: 4 | AA18: 4 | AC18: 2 | AE18: 2 | AF18: 4 | AG18: 4 | AH18: 4
A20: Overview of common sound changes
A21: b // #_{a,O} | B21: typically /b/

Sheet 002 B-
A1: A - Consonantism | D1: 1. Initial Position | I1: 1.1 Simple consonants
A3: Number | B3: 2 | F3: Latin Reference Words
A4: Treatment | B4: B- | F4: BĔLLU, BĔNE, BĬBĔRE, BILĂNCIA, BITTŪME, BĪSTIA
A5: Environment | B5: #_E
A7: Languages | B7: LAT | C7: EU POR | D7: BR POR | E7: GAL | F7: ASL | G7: CAS ESP | H7: AND ESP | I7: AMR ESP | J7: ARG | K7: CAT | L7: VAL | M7: BAL | N7: OCC | O7: GAS OCC | P7: EU FRA | Q7: QBC FRA | R7: WAL | S7: ARP | T7: LIG | U7: LMO | V7: RMH | W7: FUR | X7: LOG SRD | Y7: CPN SRD | Z7: COR | AA7: ITA | AB7: ABR | AC7: CAM | AD7: PGL | AE7: SCN | AF7: VEN | AG7: ARO | AH7: ROM
A8: Grapheme | B8: B | C8: b | D8: b | E8: b | F8: b | G8: b | H8: b | I8: b | J8: b | K8: b | L8: b | M8: b | N8: b | O8: b | P8: b | Q8: b | R8: b | S8: b | T8: b | U8: b | V8: b | W8: b | X8: b (b) | Y8: b | Z8: b | AA8: b | AB8: v? | AC8: v | AD8: v? | AE8: v | AF8: b | AG8: b | AH8: b
A9: IPA | B9: b | C9: b | D9: b | E9: b | F9: b | G9: b | H9: b | I9: b | J9: b | K9: b | L9: b | M9: b | N9: b | O9: b | P9: b | Q9: b | R9: b | S9: b | T9: b | U9: b | V9: b | W9: b | X9: b (v) | Y9: b | Z9: b | AA9: b | AC9: v | AE9: v | AF9: b | AG9: b | AH9: b
A10: IPA key | B10: 2 | C10: 2 | D10: 2 | E10: 2 | F10: 2 | G10: 2 | H10: 2 | I10: 2 | J10: 2 | K10: 2 | L10: 2 | M10: 2 | N10: 2 | O10: 2 | P10: 2 | Q10: 2 | R10: 2 | S10: 2 | T10: 2 | U10: 2 | V10: 2 | W10: 2 | X10: 273 | Y10: 2 | Z10: 2 | AA10: 2 | AC10: 43 | AE10: 43 | AF10: 2 | AG10: 2 | AH10: 2
A11: Consonantal +/− | B11: + | C11: + | D11: + | E11: + | F11: + | G11: + | H11: + | I11: + | J11: + | K11: + | L11: + | M11: + | N11: + | O11: + | P11: + | Q11: + | R11: + | S11: + | T11: + | U11: + | V11: + | W11: + | X11: + | Y11: + | Z11: + | AA11: + | AC11: + | AE11: + | AF11: + | AG11: + | AH11: +
A12: Voice +/− | B12: + | C12: + | D12: + | E12: + | F12: + | G12: + | H12: + | I12: + | J12: + | K12: + | L12: + | M12: + | N12: + | O12: + | P12: + | Q12: + | R12: + | S12: + | T12: + | U12: + | V12: + | W12: + | X12: + | Y12: + | Z12: + | AA12: + | AC12: + | AE12: + | AF12: + | AG12: + | AH12: +
A13: Sibilant +/− | B13: − | C13: − | D13: − | E13: − | F13: − | G13: − | H13: − | I13: − | J13: − | K13: − | L13: − | M13: − | N13: − | O13: − | P13: − | Q13: − | R13: − | S13: − | T13: − | U13: − | V13: − | W13: − | X13: − | Y13: − | Z13: − | AA13: − | AC13: − | AE13: − | AF13: − | AG13: − | AH13: −
A14: Lateral +/− | B14: − | C14: − | D14: − | E14: − | F14: − | G14: − | H14: − | I14: − | J14: − | K14: − | L14: − | M14: − | N14: − | O14: − | P14: − | Q14: − | R14: − | S14: − | T14: − | U14: − | V14: − | W14: − | X14: − | Y14: − | Z14: − | AA14: − | AC14: − | AE14: − | AF14: − | AG14: − | AH14: −
A15: Place of articulation | B15: B | C15: B | D15: B | E15: B | F15: B | G15: B | H15: B | I15: B | J15: B | K15: B | L15: B | M15: B | N15: B | O15: B | P15: B | Q15: B | R15: B | S15: B | T15: B | U15: B | V15: B | W15: B | X15: B | Y15: B | Z15: B | AA15: B | AC15: B | AE15: B | AF15: B | AG15: B | AH15: B
A16: Place value | B16: 3 | C16: 3 | D16: 3 | E16: 3 | F16: 3 | G16: 3 | H16: 3 | I16: 3 | J16: 3 | K16: 3 | L16: 3 | M16: 3 | N16: 3 | O16: 3 | P16: 3 | Q16: 3 | R16: 3 | S16: 3 | T16: 3 | U16: 3 | V16: 3 | W16: 3 | X16: =AVERAGE(3,3,2.5) | Y16: 3 | Z16: 3 | AA16: 3 | AC16: 2.5 | AE16: 2.5 | AF16: 3 | AG16: 3 | AH16: 3
A17: Manner of articulation | B17: P | C17: P | D17: P | E17: P | F17: P | G17: P | H17: P | I17: P | J17: P | K17: P | L17: P | M17: P | N17: P | O17: P | P17: P | Q17: P | R17: P | S17: P | T17: P | U17: P | V17: P | W17: P | X17: P (F) | Y17: P | Z17: P | AA17: P | AC17: F | AE17: F | AF17: P | AG17: P | AH17: P
A18: Sonority value | B18: 4 | C18: 4 | D18: 4 | E18: 4 | F18: 4 | G18: 4 | H18: 4 | I18: 4 | J18: 4 | K18: 4 | L18: 4 | M18: 4 | N18: 4 | O18: 4 | P18: 4 | Q18: 4 | R18: 4 | S18: 4 | T18: 4 | U18: 4 | V18: 4 | W18: 4 | X18: =AVERAGE(4,4,2) | Y18: 4 | Z18: 4 | AA18: 4 | AC18: 2 | AE18: 2 | AF18: 4 | AG18: 4 | AH18: 4
A20: Overview of common sound changes
A21: b // #_E | B21: typically /b/

Sheet 003 T-
A1: A - Consonantism | D1: 1. Initial Position | I1: 1.1 Simple consonants
A3: Number | B3: 3 | F3: Latin Reference Words
A4: Treatment | B4: T- | F4: 003a) TĒ, TĒGULA, TĬNGERE; 003b) TENĒRE, TĔRRA, TĔRTIU, TĔSTA, TĔXERE; 003c) TĪTIŌNE
A5: Environment | B5: #_E
A7: Languages | B7: LAT | C7: EU POR | D7: BR POR | E7: GAL | F7: ASL | G7: CAS ESP | H7: AND ESP | I7: AMR ESP | J7: ARG | K7: CAT | L7: VAL | M7: BAL | N7: OCC | O7: GAS OCC | P7: EU FRA | Q7: QBC FRA | R7: WAL | S7: ARP | T7: LIG | U7: LMO | V7: RMH | W7: FUR | X7: LOG SRD | Y7: CPN SRD | Z7: COR | AA7: ITA | AB7: ABR | AC7: CAM | AD7: PGL | AE7: SCN | AF7: VEN | AG7: ARO | AH7: ROM | AJ7: ARO | AK7: ROM | AM7: BR POR | AN7: QBC FRA
A8: Grapheme | B8: T | C8: t | D8: t | E8: t | F8: t | G8: t | H8: t | I8: t | J8: t | K8: t | L8: t | M8: t | N8: t | O8: t | P8: t | Q8: t | R8: t | S8: t | T8: t | U8: t | V8: t | W8: t | X8: t | Y8: t | Z8: t | AA8: t | AB8: t | AC8: t | AD8: t | AE8: t | AF8: t | AG8: t | AH8: t | AJ8: ts | AK8: ț | AM8: t | AN8: t
A9: IPA | B9: t̪ | C9: t̪ | D9: t̪ | E9: t̪ | F9: t̪ | G9: t̪ | H9: t̪ | I9: t̪ | J9: t̪ | K9: t̪ | L9: t̪ | M9: t̪ | N9: t̪ | O9: t̪ | P9: t̪ | Q9: t̪ | R9: t̪ | S9: t̪ | T9: t̪ | U9: t̪ | V9: t̪ | W9: t̪ | X9: t̪ | Y9: t̪ | Z9: t̪ | AA9: t̪ | AB9: t̪ | AC9: t̪ | AD9: t̪ | AE9: t̪ | AF9: t̪ | AG9: t̪ | AH9: t̪ | AJ9: t͡s̪ | AK9: t͡s̪ | AM9: t̠͡ʃ | AN9: t͡s̪
A10: IPA key | B10: 5 | C10: 5 | D10: 5 | E10: 5 | F10: 5 | G10: 5 | H10: 5 | I10: 5 | J10: 5 | K10: 5 | L10: 5 | M10: 5 | N10: 5 | O10: 5 | P10: 5 | Q10: 5 | R10: 5 | S10: 5 | T10: 5 | U10: 5 | V10: 5 | W10: 5 | X10: 5 | Y10: 5 | Z10: 5 | AA10: 5 | AB10: 5 | AC10: 5 | AD10: 5 | AE10: 5 | AF10: 5 | AG10: 5 | AH10: 5 | AJ10: 26 | AK10: 26 | AM10: 34 | AN10: 26
A11: Consonantal +/− | B11: + | C11: + | D11: + | E11: + | F11: + | G11: + | H11: + | I11: + | J11: + | K11: + | L11: + | M11: + | N11: + | O11: + | P11: + | Q11: + | R11: + | S11: + | T11: + | U11: + | V11: + | W11: + | X11: + | Y11: + | Z11: + | AA11: + | AB11: + | AC11: + | AD11: + | AE11: + | AF11: + | AG11: + | AH11: + | AJ11: + | AK11: + | AM11: + | AN11: +
A12: Voice +/− | B12: − | C12: − | D12: − | E12: − | F12: − | G12: − | H12: − | I12: − | J12: − | K12: − | L12: − | M12: − | N12: − | O12: − | P12: − | Q12: − | R12: − | S12: − | T12: − | U12: − | V12: − | W12: − | X12: − | Y12: − | Z12: − | AA12: − | AB12: − | AC12: − | AD12: − | AE12: − | AF12: − | AG12: − | AH12: − | AJ12: − | AK12: − | AM12: − | AN12: −
A13: Sibilant +/− | B13: − | C13: − | D13: − | E13: − | F13: − | G13: − | H13: − | I13: − | J13: − | K13: − | L13: − | M13: − | N13: − | O13: − | P13: − | Q13: − | R13: − | S13: − | T13: − | U13: − | V13: − | W13: − | X13: − | Y13: − | Z13: − | AA13: − | AB13: − | AC13: − | AD13: − | AE13: − | AF13: − | AG13: − | AH13: − | AJ13: + | AK13: + | AM13: + | AN13: +
A14: Lateral +/− | B14: − | C14: − | D14: − | E14: − | F14: − | G14: − | H14: − | I14: − | J14: − | K14: − | L14: − | M14: − | N14: − | O14: − | P14: − | Q14: − | R14: − | S14: − | T14: − | U14: − | V14: − | W14: − | X14: − | Y14: − | Z14: − | AA14: − | AB14: − | AC14: − | AD14: − | AE14: − | AF14: − | AG14: − | AH14: − | AJ14: − | AK14: − | AM14: − | AN14: −
A15: Place of articulation | B15: D | C15: D | D15: D | E15: D | F15: D | G15: D | H15: D | I15: D | J15: D | K15: D | L15: D | M15: D | N15: D | O15: D | P15: D | Q15: D | R15: D | S15: D | T15: D | U15: D | V15: D | W15: D | X15: D | Y15: D | Z15: D | AA15: D | AB15: D | AC15: D | AD15: D | AE15: D | AF15: D | AG15: D | AH15: D | AJ15: D | AK15: D | AM15: Ɉ | AN15: D
A16: Place value | B16: =5/3 | C16: =5/3 | D16: =5/3 | E16: =5/3 | F16: =5/3 | G16: =5/3 | H16: =5/3 | I16: =5/3 | ... AH16: =5/3 | AJ16: =4/3 | AK16: =4/3 | AM16: -0.5 | AN16: =4/3
A17: Manner of articulation | B17: P | C17: P | D17: P | E17: P | F17: P | G17: P | H17: P | I17: P | J17: P | K17: P | L17: P | M17: P | N17: P | O17: P | P17: P | Q17: P | R17: P | S17: P | T17: P | U17: P | V17: P | W17: P | X17: P | Y17: P | Z17: P | AA17: P | AB17: P | AC17: P | AD17: P | AE17: P | AF17: P | AG17: P | AH17: P | AJ17: P͡F | AK17: P͡F | AM17: P͡F | AN17: P͡F
A18: Sonority value | B18: 4 | C18: 4 | D18: 4 | E18: 4 | F18: 4 | G18: 4 | H18: 4 | I18: 4 | J18: 4 | K18: 4 | L18: 4 | M18: 4 | N18: 4 | O18: 4 | P18: 4 | Q18: 4 | R18: 4 | S18: 4 | T18: 4 | U18: 4 | V18: 4 | W18: 4 | X18: 4 | Y18: 4 | Z18: 4 | AA18: 4 | AB18: 4 | AC18: 4 | AD18: 4 | AE18: 4 | AF18: 4 | AG18: 4 | AH18: 4 | AJ18: 3 | AK18: 3 | AM18: 3 | AN18: 3
D19: 003a,b | AG19: 003a | AJ19: 003b,c | AM19: 003c
A20: Overview of common sound changes
A21: 003a: t // #_{ĕNC,ē,ĭ} | B21: typically /t/
A22: 003b: t / ? / #_{ĕ²} | B22: typically /t/
B23: /t͡s/ in ARO,ROM
A24: 003c: t / ? / #_ī | B24: typically /t/
B25: /t͡ʃ/ in BR.POR
B26: /t͡s/ in ARO,ROM
A28: Romanian: t͡s̪ | B28: 1) ē; ĭ; stressed /ĕ/~/æ/ followed by a cluster /NC/ (> ERom. /e/) 2) stressed /ĕ/~/æ/ *not* followed by a cluster /NC/ (> ERom. /je/) 3) i + vowel (consonantal /i/) (> ERom. /j/) 4) long /i:/ (> ERom. /i/), if not elided

Sheet 004 T-
A1: A - Consonantism | D1: 1. Initial Position | I1: 1.1 Simple consonants
A3: Number | B3: 4 | F3: Latin Reference Words
A4: Treatment | B4: T- | F4: TĀBŬLA, TĂNGERE, TĂXU/TAXŎNE, TOCCĀRE, TŎRCULU, TŬRRE, TŪ
A5: Environment | B5: #_{a,O}
A7: Languages | B7: LAT | C7: EU POR | D7: BR POR | E7: GAL | F7: ASL | G7: CAS ESP | H7: AND ESP | I7: AMR ESP | J7: ARG | K7: CAT | L7: VAL | M7: BAL | N7: OCC | O7: GAS OCC | P7: EU FRA | Q7: QBC FRA | R7: WAL | S7: ARP | T7: LIG | U7: LMO | V7: RMH | W7: FUR | X7: LOG SRD | Y7: CPN SRD | Z7: COR | AA7: ITA | AB7: ABR | AC7: CAM | AD7: PGL | AE7: SCN | AF7: VEN | AG7: ARO | AH7: ROM | AJ7: QBC FRA
A8: Grapheme | B8: T | C8: t | D8: t | E8: t | F8: t | G8: t | H8: t | I8: t | J8: t | K8: t | L8: t | M8: t | N8: t | O8: t | P8: t | Q8: t | R8: t | S8: t | T8: t | U8: t | V8: t | W8: t | X8: t | Y8: t | Z8: t | AA8: t | AB8: t | AC8: t | AD8: t | AE8: t | AF8: t | AG8: t | AH8: t | AJ8: t
A9: IPA | B9: t̪ | C9: t̪ | D9: t̪ | E9: t̪ | F9: t̪ | G9: t̪ | H9: t̪ | I9: t̪ | J9: t̪ | K9: t̪ | L9: t̪ | M9: t̪ | N9: t̪ | O9: t̪ | P9: t̪ | Q9: t̪ | R9: t̪ | S9: t̪ | T9: t̪ | U9: t̪ | V9: t̪ | W9: t̪ | X9: t̪ | Y9: t̪ | Z9: t̪ | AA9: t̪ | AB9: t̪ | AC9: t̪ | AD9: t̪ | AE9: t̪ | AF9: t̪ | AG9: t̪ | AH9: t̪ | AJ9: t͡s̪
A10: IPA key | B10: 5 | C10: 5 | D10: 5 | E10: 5 | F10: 5 | G10: 5 | H10: 5 | I10: 5 | J10: 5 | K10: 5 | L10: 5 | M10: 5 | N10: 5 | O10: 5 | P10: 5 | Q10: 5 | R10: 5 | S10: 5 | T10: 5 | U10: 5 | V10: 5 | W10: 5 | X10: 5 | Y10: 5 | Z10: 5 | AA10: 5 | AB10: 5 | AC10: 5 | AD10: 5 | AE10: 5 | AF10: 5 | AG10: 5 | AH10: 5 | AJ10: 26
A11: Consonantal +/− | B11: + | C11: + | D11: + | E11: + | F11: + | G11: + | H11: + | I11: + | J11: + | K11: + | L11: + | M11: + | N11: + | O11: + | P11: + | Q11: + | R11: + | S11: + | T11: + | U11: + | V11: + | W11: + | X11: + | Y11: + | Z11: + | AA11: + | AB11: + | AC11: + | AD11: + | AE11: + | AF11: + | AG11: + | AH11: + | AJ11: +
A12: Voice +/− | B12: − | C12: − | D12: − | E12: − | F12: − | G12: − | H12: − | I12: − | J12: − | K12: − | L12: − | M12: − | N12: − | O12: − | P12: − | Q12: − | R12: − | S12: − | T12: − | U12: − | V12: − | W12: − | X12: − | Y12: − | Z12: − | AA12: − | AB12: − | AC12: − | AD12: − | AE12: − | AF12: − | AG12: − | AH12: − | AJ12: −
A13: Sibilant +/− | B13: − | C13: − | D13: − | E13: − | F13: − | G13: − | H13: − | I13: − | J13: − | K13: − | L13: − | M13: − | N13: − | O13: − | P13: − | Q13: − | R13: − | S13: − | T13: − | U13: − | V13: − | W13: − | X13: − | Y13: − | Z13: − | AA13: − | AB13: − | AC13: − | AD13: − | AE13: − | AF13: − | AG13: − | AH13: − | AJ13: +
A14: Lateral +/− | B14: − | C14: − | D14: − | E14: − | F14: − | G14: − | H14: − | I14: − | J14: − | K14: − | L14: − | M14: − | N14: − | O14: − | P14: − | Q14: − | R14: − | S14: − | T14: − | U14: − | V14: − | W14: − | X14: − | Y14: − | Z14: − | AA14: − | AB14: − | AC14: − | AD14: − | AE14: − | AF14: − | AG14: − | AH14: − | AJ14: −
A15: Place of articulation | B15: D | C15: D | D15: D | E15: D | F15: D | G15: D | H15: D | I15: D | J15: D | K15: D | L15: D | M15: D | N15: D | O15: D | P15: D | Q15: D | R15: D | S15: D | T15: D | U15: D | V15: D | W15: D | X15: D | Y15: D | Z15: D | AA15: D | AB15: D | AC15: D | AD15: D | AE15: D | AF15: D | AG15: D | AH15: D | AJ15: D
A16: Place value | B16: =5/3 | C16: =5/3 | D16: =5/3 | E16: =5/3 | F16: =5/3 | G16: =5/3 | H16: =5/3 | I16: =5/3 | ... AH16: =5/3 | AJ16: =4/3
A17: Manner of articulation | B17: P | C17: P | D17: P | E17: P | F17: P | G17: P | H17: P | I17: P | J17: P | K17: P | L17: P | M17: P | N17: P | O17: P | P17: P | Q17: P | R17: P | S17: P | T17: P | U17: P | V17: P | W17: P | X17: P | Y17: P | Z17: P | AA17: P | AB17: P | AC17: P | AD17: P | AE17: P | AF17: P | AG17: P | AH17: P | AJ17: P͡F
A18: Sonority value | B18: 4 | C18: 4 | D18: 4 | E18: 4 | F18: 4 | G18: 4 | H18: 4 | I18: 4 | J18: 4 | K18: 4 | L18: 4 | M18: 4 | N18: 4 | O18: 4 | P18: 4 | Q18: 4 | R18: 4 | S18: 4 | T18: 4 | U18: 4 | V18: 4 | W18: 4 | X18: 4 | Y18: 4 | Z18: 4 | AA18: 4 | AB18: 4 | AC18: 4 | AD18: 4 | AE18: 4 | AF18: 4 | AG18: 4 | AH18: 4 | AJ18: 3
Q19: 004a | AJ19: 004b
A20: Overview of common sound changes
A21: 004a: t // #_{a,o,ŭ} | B21: typically /t/
A22: 004b: t // #_ū | B22: typically /t/

Sheet 005 D-
A1: A - Consonantism | D1: 1. Initial Position | I1: 1.1 Simple consonants
A3: Number | B3: 5 | F3: Latin Reference Words
A4: Treatment | B4: D- | F4: 005a) DĒ, DĒBĒRE, DĔNTE, DĬGĬTU; 005b) DĔCE, DĪCERE, DĪĒ/DĪA, DĪĀNA
A5: Environment | B5: #_E
A7: Languages | B7: LAT | C7: EU POR | D7: BR POR | E7: GAL | F7: ASL | G7: CAS ESP | H7: AND ESP | I7: AMR ESP | J7: ARG | K7: CAT | L7: VAL | M7: BAL | N7: OCC | O7: GAS OCC | P7: EU FRA | Q7: QBC FRA | R7: WAL | S7: ARP | T7: LIG | U7: LMO | V7: RMH | W7: FUR | X7: LOG SRD | Y7: CPN SRD | Z7: COR | AA7: ITA | AB7: ABR | AC7: CAM | AD7: PGL | AE7: SCN | AF7: VEN | AG7: ARO | AH7: ROM | AJ7: ARO | AK7: ROM | AM7: BR POR | AQ7: QBC FRA
A8: Grapheme | B8: D | C8: d | D8: d | E8: d | F8: d | G8: d | H8: d | I8: d | J8: d | K8: d | L8: d | M8: d | N8: d | O8: d | P8: d | Q8: d | R8: d | S8: d | U8: d | V8: d | W8: d | X8: d | Y8: d | AA8: d | AB8: d | AC8: d | AD8: d | AE8: d | AF8: d | AG8: d | AH8: d | AJ8: dz | AK8: z | AM8: d | AQ8: d
A9: IPA | B9: d̪ | C9: d̪ | D9: d̪ | E9: d̪ | F9: d̪ | G9: d̪ | H9: d̪ | I9: d̪ | J9: d̪ | K9: d̪ | L9: d̪ | M9: d̪ | N9: d̪ | O9: d̪ | P9: d̪ | Q9: d̪ | R9: d̪ | S9: d̪ | U9: d̪ | V9: d̪ | W9: d̪ | X9: d̪ | Y9: d̪ | AA9: d̪ | AB9: d̪ | AC9: d̪~ɾ | AD9: d̪ | AE9: d̪~ɾ | AF9: d̪ | AG9: d̪ | AH9: d̪ | AJ9: d͡z̪ | AK9: z̪ | AM9: d̠͡ʒ | AQ9: d͡z̪
A10: IPA key | B10: 6 | C10: 6 | D10: 6 | E10: 6 | F10: 6 | G10: 6 | H10: 6 | I10: 6 | J10: 6 | K10: 6 | L10: 6 | M10: 6 | N10: 6 | O10: 6 | P10: 6 | Q10: 6 | R10: 6 | S10: 6 | U10: 6 | V10: 6 | W10: 6 | X10: 6 | Y10: 6 | AA10: 6 | AB10: 6 | AC10: 101 | AD10: 6 | AE10: 101 | AF10: 6 | AG10: 6 | AH10: 6 | AJ10: 27 | AK10: 49 | AM10: 35 | AQ10: 27
A11: Consonantal +/− | B11: + | C11: + | D11: + | E11: + | F11: + | G11: + | H11: + | I11: + | J11: + | K11: + | L11: + | M11: + | N11: + | O11: + | P11: + | Q11: + | R11: + | S11: + | U11: + | V11: + | W11: + | X11: + | Y11: + | AA11: + | AB11: + | AC11: + | AD11: + | AE11: + | AF11: + | AG11: + | AH11: + | AJ11: + | AK11: + | AM11: + | AQ11: +
A12: Voice +/− | B12: + | C12: + | D12: + | E12: + | F12: + | G12: + | H12: + | I12: + | J12: + | K12: + | L12: + | M12: + | N12: + | O12: + | P12: + | Q12: + | R12: + | S12: + | U12: + | V12: + | W12: + | X12: + | Y12: + | AA12: + | AB12: + | AC12: + | AD12: + | AE12: + | AF12: + | AG12: + | AH12: + | AJ12: + | AK12: + | AM12: + | AQ12: +
A13: Sibilant +/− | B13: − | C13: − | D13: − | E13: − | F13: − | G13: − | H13: − | I13: − | J13: − | K13: − | L13: − | M13: − | N13: − | O13: − | P13: − | Q13: − | R13: − | S13: − | U13: − | V13: − | W13: − | X13: − | Y13: − | AA13: − | AB13: − | AC13: − | AD13: − | AE13: − | AF13: − | AG13: − | AH13: − | AJ13: + | AK13: + | AM13: + | AQ13: +
A14: Lateral +/− | B14: − | C14: − | D14: − | E14: − | F14: − | G14: − | H14: − | I14: − | J14: − | K14: − | L14: − | M14: − | N14: − | O14: − | P14: − | Q14: − | R14: − | S14: − | U14: − | V14: − | W14: − | X14: − | Y14: − | AA14: − | AB14: − | AC14: − | AD14: − | AE14: − | AF14: − | AG14: − | AH14: − | AJ14: − | AK14: − | AM14: − | AQ14: −
A15: Place of articulation | B15: D | C15: D | D15: D | E15: D | F15: D | G15: D | H15: D | I15: D | J15: D | K15: D | L15: D | M15: D | N15: D | O15: D | P15: D | Q15: D | R15: D | S15: D | U15: D | V15: D | W15: D | X15: D | Y15: D | AA15: D | AB15: D | AC15: D | AD15: D | AE15: D | AF15: D | AG15: D | AH15: D | AJ15: D | AK15: D | AM15: Ɉ | AQ15: D
A16: Place value | B16: =5/3 | C16: =5/3 | D16: =5/3 | E16: =5/3 | F16: =5/3 | G16: =5/3 | H16: =5/3 | I16: =5/3 | ... S16: =5/3 | U16: =5/3 | V16: =5/3 | W16: =5/3 | X16: =5/3 | Y16: =5/3 | AA16: =5/3 | AB16: =5/3 | AC16: =AVERAGE(5/3,0.75) | AD16: =5/3 | AE16: =AVERAGE(5/3,0.75) | AF16: =5/3 | AG16: =5/3 | AH16: =5/3 | AJ16: =4/3 | AK16: =4/3 | AM16: -0.5 | AQ16: =4/3
A17: Manner of articulation | B17: P | C17: P | D17: P | E17: P | F17: P | G17: P | H17: P | I17: P | J17: P | K17: P | L17: P | M17: P | N17: P | O17: P | P17: P | Q17: P | R17: P | S17: P | U17: P | V17: P | W17: P | X17: P | Y17: P | AA17: P | AB17: P | AC17: P~L | AD17: P | AE17: P~L | AF17: P | AG17: P | AH17: P | AJ17: P͡F | AK17: F | AM17: P͡F | AQ17: P͡F
A18: Sonority value | B18: 4 | C18: 4 | D18: 4 | E18: 4 | F18: 4 | G18: 4 | H18: 4 | I18: 4 | J18: 4 | K18: 4 | L18: 4 | M18: 4 | N18: 4 | O18: 4 | P18: 4 | Q18: 4 | R18: 4 | S18: 4 | U18: 4 | V18: 4 | W18: 4 | X18: 4 | Y18: 4 | AA18: 4 | AB18: 4 | AC18: =AVERAGE(4,0.875) | AD18: 4 | AE18: =AVERAGE(4,0.875) | AF18: 4 | AG18: 4 | AH18: 4 | AJ18: 3 | AK18: 2 | AM18: 3 | AQ18: 3
D19: 005a,b | Q19: 005a,b | AG19: 005a | AJ19: 005b,c | AM19: 005c
A20: Overview of common sound changes
A21: 005a: d // #_{ĕNC,ē,ĭ} | B21: typically /d/
A22: 005b: d /? / #_{ĕ³} | B22: typically /d/
B23: /d͡z/ in ARO, /z/ in ROM
A24: 005c: d / ? / #_ī | B24: typically /d/
B25: /d͡ʒ/ in BR.POR
B26: /d͡z/ in ARO, QBC.FRA, /z/ in ROM
A28: Romanian: t͡s̪ | B28: 1) ē; ĭ; stressed /ĕ/~/æ/ followed by a cluster /NC/ (> ERom. /e/) 2) stressed /ĕ/~/æ/ *not* followed by a cluster /NC/ (> ERom. /je/) 3) i + vowel (consonantal /i/) (> ERom. /j/) 4) long /i:/ (> ERom. /i/), if not elided

Sheet 006 D-
A1: A - Consonantism | D1: 1. Initial Position | I1: 1.1 Simple consonants
A3: Number | B3: 6 | F3: Latin Reference Words
A4: Treatment | B4: D- | F4: DĂMNU, DĂRE, DŎMĬNA, DORMĪRE, DŬLCE, DŬO(S)
A5: Environment | B5: #_{a,O}
A7: Languages | B7: LAT | C7: EU POR | D7: BR POR | E7: GAL | F7: ASL | G7: CAS ESP | H7: AND ESP | I7: AMR ESP | J7: ARG | K7: CAT | L7: VAL | M7: BAL | N7: OCC | O7: GAS OCC | P7: EU FRA | Q7: QBC FRA | R7: WAL | S7: ARP | T7: LIG | U7: LMO | V7: RMH | W7: FUR | X7: LOG SRD | Y7: CPN SRD | Z7: COR | AA7: ITA | AB7: ABR | AC7: CAM | AD7: PGL | AE7: SCN | AF7: VEN | AG7: ARO | AH7: ROM | AJ7: QBC FRA
A8: Grapheme | B8: D | C8: d | D8: d | E8: d | F8: d | G8: d | H8: d | I8: d | J8: d | K8: d | L8: d | M8: d | N8: d | O8: d | P8: d | Q8: d | R8: d | S8: d | U8: d | V8: d | W8: d | X8: d | Y8: d | AA8: d | AB8: d | AC8: d | AD8: d | AE8: d | AF8: d | AG8: d | AH8: d | AJ8: d
A9: IPA | B9: d̪ | C9: d̪ | D9: d̪ | E9: d̪ | F9: d̪ | G9: d̪ | H9: d̪ | I9: d̪ | J9: d̪ | K9: d̪ | L9: d̪ | M9: d̪ | N9: d̪ | O9: d̪ | P9: d̪ | Q9: d̪ | R9: d̪ | S9: d̪ | U9: d̪ | V9: d̪ | W9: d̪ | X9: d̪ | Y9: d̪ | AA9: d̪ | AB9: d̪ | AC9: d̪~ɾ | AD9: d̪ | AE9: d̪~ɾ | AF9: d̪ | AG9: d̪ | AH9: d̪ | AJ9: d͡z̪
A10: IPA key | B10: 6 | C10: 6 | D10: 6 | E10: 6 | F10: 6 | G10: 6 | H10: 6 | I10: 6 | J10: 6 | K10: 6 | L10: 6 | M10: 6 | N10: 6 | O10: 6 | P10: 6 | Q10: 6 | R10: 6 | S10: 6 | U10: 6 | V10: 6 | W10: 6 | X10: 6 | Y10: 6 | AA10: 6 | AB10: 6 | AC10: 101 | AD10: 6 | AE10: 101 | AF10: 6 | AG10: 6 | AH10: 6 | AJ10: 27
A11: Consonantal +/− | B11: + | C11: + | D11: + | E11: + | F11: + | G11: + | H11: + | I11: + | J11: + | K11: + | L11: + | M11: + | N11: + | O11: + | P11: + | Q11: + | R11: + | S11: + | U11: + | V11: + | W11: + | X11: + | Y11: + | AA11: + | AB11: + | AC11: + | AD11: + | AE11: + | AF11: + | AG11: + | AH11: + | AJ11: +
A12: Voice +/− | B12: + | C12: + | D12: + | E12: + | F12: + | G12: + | H12: + | I12: + | J12: + | K12: + | L12: + | M12: + | N12: + | O12: + | P12: + | Q12: + | R12: + | S12: + | U12: + | V12: + | W12: + | X12: + | Y12: + | AA12: + | AB12: + | AC12: + | AD12: + | AE12: + | AF12: + | AG12: + | AH12: + | AJ12: +
A13: Sibilant +/− | B13: − | C13: − | D13: − | E13: − | F13: − | G13: − | H13: − | I13: − | J13: − | K13: − | L13: − | M13: − | N13: − | O13: − | P13: − | Q13: − | R13: − | S13: − | U13: − | V13: − | W13: − | X13: − | Y13: − | AA13: − | AB13: − | AC13: − | AD13: − | AE13: − | AF13: − | AG13: − | AH13: − | AJ13: +
A14: Lateral +/− | B14: − | C14: − | D14: − | E14: − | F14: − | G14: − | H14: − | I14: − | J14: − | K14: − | L14: − | M14: − | N14: − | O14: − | P14: − | Q14: − | R14: − | S14: − | U14: − | V14: − | W14: − | X14: − | Y14: − | AA14: − | AB14: − | AC14: − | AD14: − | AE14: − | AF14: − | AG14: − | AH14: − | AJ14: −
A15: Place of articulation | B15: D | C15: D | D15: D | E15: D | F15: D | G15: D | H15: D | I15: D | J15: D | K15: D | L15: D | M15: D | N15: D | O15: D | P15: D | Q15: D | R15: D | S15: D | U15: D | V15: D | W15: D | X15: D | Y15: D | AA15: D | AB15: D | AC15: D | AD15: D | AE15: D | AF15: D | AG15: D | AH15: D | AJ15: D
A16: Place value | B16: =5/3 | C16: =5/3 | D16: =5/3 | E16: =5/3 | F16: =5/3 | G16: =5/3 | H16: =5/3 | I16: =5/3 | ... S16: =5/3 | U16: =5/3 | V16: =5/3 | W16: =5/3 | X16: =5/3 | Y16: =5/3 | AA16: =5/3 | AB16: =5/3 | AC16: =AVERAGE(5/3,0.75) | AD16: =5/3 | AE16: =AVERAGE(5/3,0.75) | AF16: =5/3 | AG16: =5/3 | AH16: =5/3 | AJ16: =4/3
A17: Manner of articulation | B17: P | C17: P | D17: P | E17: P | F17: P | G17: P | H17: P | I17: P | J17: P | K17: P | L17: P | M17: P | N17: P | O17: P | P17: P | Q17: P | R17: P | S17: P | U17: P | V17: P | W17: P | X17: P | Y17: P | AA17: P | AB17: P | AC17: P~L | AD17: P | AE17: P~L | AF17: P | AG17: P | AH17: P | AJ17: P͡F
A18: Sonority value | B18: 4 | C18: 4 | D18: 4 | E18: 4 | F18: 4 | G18: 4 | H18: 4 | I18: 4 | J18: 4 | K18: 4 | L18: 4 | M18: 4 | N18: 4 | O18: 4 | P18: 4 | Q18: 4 | R18: 4 | S18: 4 | U18: 4 | V18: 4 | W18: 4 | X18: 4 | Y18: 4 | AA18: 4 | AB18: 4 | AC18: =AVERAGE(4,0.875) | AD18: 4 | AE18: =AVERAGE(4,0.875) | AF18: 4 | AG18: 4 | AH18: 4 | AJ18: 3
Q19: 006a | AJ19: 006b
A20: Overview of common sound changes
A21: 006a: d // #_{a,o,ŭ} | B21: typically /d/
A22: 006b: d // #_ū | B22: typically /t/

Sheet 007 C-
A1: A - Consonantism | D1: 1. Initial Position | I1: 1.1 Simple consonants
A3: Number | B3: 7 | F3: Latin Reference Words
A4: Treatment | B4: C- | F4: 007a: CĬNĔRE, CÆLU, CĔRĔBĔLLU, CĔNTU, CĔRĔSĔA, CĒPA, CĬCĔRU, CĬLĬU; 007b: CĪNCTU, CĪMĬCE, CĪVĬTĀTE, CĪCCU
A5: Environment | B5: #_E
A7: Languages | B7: LAT | C7: EU POR | D7: BR POR | E7: GAL | F7: ASL | G7: CAS ESP | H7: AND ESP | I7: AMR ESP | J7: ARG | K7: CAT | L7: VAL | M7: BAL | N7: OCC | O7: GAS OCC | P7: EU FRA | Q7: QBC FRA | R7: WAL | S7: ARP | T7: LIG | U7: LMO | V7: RMH | W7: FUR | X7: LOG SRD | Y7: CPN SRD | Z7: COR | AA7: ITA | AB7: ABR | AC7: CAM | AD7: PGL | AE7: SCN | AF7: VEN | AG7: ARO | AH7: ROM
A8: Grapheme | B8: C | C8: c | D8: c | E8: c | F8: c | G8: c | H8: c | I8: c | J8: c | K8: c | L8: c | M8: c | N8: c | O8: c | P8: c | Q8: c | R8: c | S8: c | U8: sc | V8: tsch | W8: c | X8: ch | Y8: c | AA8: c | AC8: c | AE8: c | AF8: s/th | AG8: ts | AH8: c
A9: IPA | B9: k | C9: s (s̪) | D9: s | E9: θ (s) | F9: θ | G9: θ | H9: s̟ | I9: s | J9: θ | K9: s̠ | L9: s̠ | M9: s̠ | N9: s̠ | O9: s̠ | P9: s̪ | Q9: s̪ | R9: s̪ | S9: s̪ | U9: ʃ~s̠ | V9: t̠͡ʃ | W9: t̠͡ʃ~s̠ | X9: k | Y9: t̠͡ʃ | AA9: t̠͡ʃ | AC9: t̠͡ʃ | AE9: t̠͡ʃ | AF9: s̠~θ | AG9: t͡s̪ | AH9: t̠͡ʃ
A10: IPA key | B10: 19 | C10: 120 | D10: 50 | E10: 102 | F10: 44 | G10: 44 | H10: 46 | I10: 50 | J10: 44 | K10: 52 | L10: 52 | M10: 52 | N10: 52 | O10: 52 | P10: 48 | Q10: 48 | R10: 48 | S10: 48 | U10: 103 | V10: 34 | X10: 19 | Y10: 34 | AA10: 34 | AC10: 34 | AE10: 34 | AF10: 104 | AG10: 26 | AH10: 34
A11: Consonantal +/− | B11: + | C11: + | D11: + | E11: + | F11: + | G11: + | H11: + | I11: + | J11: + | K11: + | L11: + | M11: + | N11: + | O11: + | P11: + | Q11: + | R11: + | S11: + | U11: + | V11: + | X11: + | Y11: + | AA11: + | AC11: + | AE11: + | AF11: + | AG11: + | AH11: +
A12: Voice +/− | B12: − | C12: − | D12: − | E12: − | F12: − | G12: − | H12: − | I12: − | J12: − | K12: − | L12: − | M12: − | N12: − | O12: − | P12: − | Q12: − | R12: − | S12: − | U12: − | V12: − | X12: − | Y12: − | AA12: − | AC12: − | AE12: − | AF12: − | AG12: − | AH12: −
A13: Sibilant +/− | B13: − | C13: + | D13: + | E13: +/− | F13: − | G13: − | H13: + | I13: + | J13: − | K13: + | L13: + | M13: + | N13: + | O13: + | P13: + | Q13: + | R13: + | S13: + | U13: + | V13: + | X13: − | Y13: + | AA13: + | AC13: + | AE13: + | AF13: +/− | AG13: + | AH13: +
A14: Lateral +/− | B14: − | C14: − | D14: − | E14: − | F14: − | G14: − | H14: − | I14: − | J14: − | K14: − | L14: − | M14: − | N14: − | O14: − | P14: − | Q14: − | R14: − | S14: − | U14: − | V14: − | X14: − | Y14: − | AA14: − | AC14: − | AE14: − | AF14: − | AG14: − | AH14: −
A15: Place of articulation | B15: K | C15: D | D15: D | E15: D | F15: D | G15: D | H15: D | I15: D | J15: D | K15: D | L15: D | M15: D | N15: D | O15: D | P15: D | Q15: D | R15: D | S15: D | U15: Ɉ~D | V15: Ɉ | X15: K | Y15: Ɉ | AA15: Ɉ | AC15: Ɉ | AE15: Ɉ | AF15: D | AG15: D | AH15: Ɉ
A16: Place value | B16: -3 | C16: =13/12 | D16: 1 | E16: =AVERAGE(2,2,1) | F16: 2 | G16: 2 | H16: =5/3 | I16: 1 | J16: 2 | K16: 0.5 | L16: 0.5 | M16: 0.5 | N16: 0.5 | O16: 0.5 | P16: =4/3 | Q16: =4/3 | R16: =4/3 | S16: =4/3 | U16: =AVERAGE(-0.5,0.5) | V16: -0.5 | X16: -3 | Y16: -0.5 | AA16: -0.5 | AC16: -0.5 | AE16: -0.5 | AF16: =AVERAGE(0.5,2) | AG16: =4/3 | AH16: -0.5
A17: Manner of articulation | B17: P | C17: F | D17: F | E17: F | F17: F | G17: F | H17: F | I17: F | J17: F | K17: F | L17: F | M17: F | N17: F | O17: F | P17: F | Q17: F | R17: F | S17: F | U17: F | V17: P͡F | X17: P | Y17: P͡F | AA17: P͡F | AC17: P͡F | AE17: P͡F | AF17: F | AG17: P͡F | AH17: P͡F
A18: Sonority value | B18: 4 | C18: 2 | D18: 2 | E18: 2 | F18: 2 | G18: 2 | H18: 2 | I18: 2 | J18: 2 | K18: 2 | L18: 2 | M18: 2 | N18: 2 | O18: 2 | P18: 2 | Q18: 2 | R18: 2 | S18: 2 | U18: 2 | V18: 3 | X18: 4 | Y18: 3 | AA18: 3 | AC18: 3 | AE18: 3 | AF18: 2 | AG18: 3 | AH18: 3
A20: Overview of common sound changes
A21: 007a: k / ? / #_{e,ĭ} | B21: /k/ in LOG.SRD, DAL
B22: /t͡ʃ/ in ITA, ROM
B23: /s/ in POR, AND.ESP, AMR.ESP, CVB, FRA
B24: /θ/ in CAS.ESP
A26: 007b: k / ? / #_ī | B26: /k/ in LOG.SRD
B27: /t͡ʃ/ in ITA, ROM
B28: /s/ in POR, AND.ESP, AMR.ESP, CVB, FRA
B29: /θ/ in CAS.ESP

Sheet 008 C-
A1: A - Consonantism | D1: 1. Initial Position | I1: 1.1 Simple consonants
A3: Number | B3: 8 | F3: Latin Reference Words
A4: Treatment | B4: C- | F4: 008a: CĂPRA, CĂRBŌNE, CĂNTĀRE; 008b: CĂTTU, CĂRY̆ŎPHY̆LLU
A5: Environment | B5: #_a
A7: Languages | B7: LAT | C7: EU POR | D7: BR POR | E7: GAL | F7: ASL | G7: CAS ESP | H7: AND ESP | I7: AMR ESP | J7: ARG | K7: CAT | L7: VAL | M7: BAL | N7: OCC | O7: GAS OCC | P7: EU FRA | Q7: QBC FRA | R7: WAL | S7: ARP | T7: LIG | U7: LMO | V7: RMH | W7: FUR | X7: LOG SRD | Y7: CPN SRD | Z7: COR | AA7: ITA | AB7: ABR | AC7: CAM | AD7: PGL | AE7: SCN | AF7: VEN | AG7: ARO | AH7: ROM
A8: Grapheme | B8: C | C8: c | D8: c | E8: c | F8: c | G8: c | H8: c | I8: c | J8: c | K8: c | L8: c | M8: c | N8: c (ch) | O8: c | P8: ch | Q8: ch | R8: tch | S8: ch | T8: c | U8: c | V8: ch | W8: cj | X8: c | Y8: c | Z8: c | AA8: c | AB8: c | AC8: c | AD8: c | AE8: c | AF8: c | AG8: c | AH8: c
A9: IPA | B9: k | C9: k | D9: k | E9: k | F9: k | G9: k | H9: k | I9: k | J9: k | K9: k | L9: k | M9: k | N9: k (t͡s) | O9: k | P9: ʃ | Q9: ʃ | R9: t̠͡ʃ | S9: t̠͡ʃ~θ | T9: k | U9: k | V9: k~c | W9: c~t̠͡ʃ | X9: k | Y9: k | Z9: k | AA9: k | AB9: k | AC9: k | AD9: k | AE9: k | AF9: k | AG9: k | AH9: k
A10: IPA key | B10: 19 | C10: 19 | D10: 19 | E10: 19 | F10: 19 | G10: 19 | H10: 19 | I10: 19 | J10: 19 | K10: 19 | L10: 19 | M10: 19 | N10: 105 | O10: 19 | P10: 56 | Q10: 56 | R10: 34 | S10: 106 | T10: 19 | U10: 19 | V10: 150 | W10: 152 | X10: 19 | Y10: 19 | Z10: 19 | AA10: 19 | AB10: 19 | AC10: 19 | AD10: 19 | AE10: 19 | AF10: 19 | AG10: 19 | AH10: 19
A11: Consonantal +/− | B11: + | C11: + | D11: + | E11: + | F11: + | G11: + | H11: + | I11: + | J11: + | K11: + | L11: + | M11: + | N11: + | O11: + | P11: + | Q11: + | R11: + | S11: + | T11: + | U11: + | V11: + | W11: + | X11: + | Y11: + | Z11: + | AA11: + | AB11: + | AC11: + | AD11: + | AE11: + | AF11: + | AG11: + | AH11: +
A12: Voice +/− | B12: − | C12: − | D12: − | E12: − | F12: − | G12: − | H12: − | I12: − | J12: − | K12: − | L12: − | M12: − | N12: − | O12: − | P12: − | Q12: − | R12: − | S12: − | T12: − | U12: − | V12: − | W12: − | X12: − | Y12: − | Z12: − | AA12: − | AB12: − | AC12: − | AD12: − | AE12: − | AF12: − | AG12: − | AH12: −
A13: Sibilant +/− | B13: − | C13: − | D13: − | E13: − | F13: − | G13: − | H13: − | I13: − | J13: − | K13: − | L13: − | M13: − | N13: −/+ | O13: − | P13: + | Q13: + | R13: + | S13: + (−) | T13: − | U13: − | V13: − | W13: −/+ | X13: − | Y13: − | Z13: − | AA13: − | AB13: − | AC13: − | AD13: − | AE13: − | AF13: − | AG13: − | AH13: −
A14: Lateral +/− | B14: − | C14: − | D14: − | E14: − | F14: − | G14: − | H14: − | I14: − | J14: − | K14: − | L14: − | M14: − | N14: − | O14: − | P14: − | Q14: − | R14: − | S14: − | T14: − | U14: − | V14: − | W14: − | X14: − | Y14: − | Z14: − | AA14: − | AB14: − | AC14: − | AD14: − | AE14: − | AF14: − | AG14: − | AH14: −
A15: Place of articulation | B15: K | C15: K | D15: K | E15: K | F15: K | G15: K | H15: K | I15: K | J15: K | K15: K | L15: K | M15: K | N15: K (Ɉ) | O15: K | P15: Ɉ | Q15: Ɉ | R15: Ɉ | S15: Ɉ~D | T15: K | U15: K | V15: K~Ɉ | W15: Ɉ | X15: K | Y15: K | Z15: K | AA15: K | AB15: K | AC15: K | AD15: K | AE15: K | AF15: K | AG15: K | AH15: K
A16: Place value | B16: -3 | C16: -3 | D16: -3 | E16: -3 | F16: -3 | G16: -3 | H16: -3 | I16: -3 | J16: -3 | K16: -3 | L16: -3 | M16: -3 | N16: =AVERAGE(3,3,1) | O16: -3 | P16: -0.5 | Q16: -0.5 | R16: -0.5 | S16: =AVERAGE(-0.5,2) | T16: -3 | U16: -3 | V16: -2.5 | W16: =AVERAGE(-2,-0.5) | X16: -3 | Y16: -3 | Z16: -3 | AA16: -3 | AB16: -3 | AC16: -3 | AD16: -3 | AE16: -3 | AF16: -3 | AG16: -3 | AH16: -3
A17: Manner of articulation | B17: P | C17: P | D17: P | E17: P | F17: P | G17: P | H17: P | I17: P | J17: P | K17: P | L17: P | M17: P | N17: P (P͡F) | O17: P | P17: F | Q17: F | R17: P͡F | S17: P͡F~F | T17: P | U17: P | V17: P | W17: P~P͡F | X17: P | Y17: P | Z17: P | AA17: P | AB17: P | AC17: P | AD17: P | AE17: P | AF17: P | AG17: P | AH17: P
A18: Sonority value | B18: 4 | C18: 4 | D18: 4 | E18: 4 | F18: 4 | G18: 4 | H18: 4 | I18: 4 | J18: 4 | K18: 4 | L18: 4 | M18: 4 | N18: =AVERAGE(4,4,3) | O18: 4 | P18: 2 | Q18: 2 | R18: 3 | S18: =AVERAGE(3,2) | T18: 4 | U18: 4 | V18: 4 | W18: =AVERAGE(4,3) | X18: 4 | Y18: 4 | Z18: 4 | AA18: 4 | AB18: 4 | AC18: 4 | AD18: 4 | AE18: 4 | AF18: 4 | AG18: 4 | AH18: 4
A20: Overview of common sound changes
A21: 008a: k / ? / #_a | B21: typically /k/
B22: palatalized to /(t)ʃ/ in Gallo-Romance
A23: 008b: k / ɡ / #_a | B23: typically /ɡ/
B24: palatalized to /(d)ʒ/ in Gallo-Romance

Sheet 009 C-
A1: A - Consonantism | D1: 1. Initial Position | I1: 1.1 Simple consonants
A3: Number | B3: 9 | F3: Latin Reference Words
A4: Treatment | B4: C- | F4: 009a) CŎCERE, CŎLLU, CŎLŌRE, CŬM, CŬNĪCŬLU; 009b) CŬBĬTU
A5: Environment | B5: #_{o,ŭ}
A7: Languages | B7: LAT | C7: EU POR | D7: BR POR | E7: GAL | F7: ASL | G7: CAS ESP | H7: AND ESP | I7: AMR ESP | J7: ARG | K7: CAT | L7: VAL | M7: BAL | N7: OCC | O7: GAS OCC | P7: EU FRA | Q7: QBC FRA | R7: WAL | S7: ARP | T7: LIG | U7: LMO | V7: RMH | W7: FUR | X7: LOG SRD | Y7: CPN SRD | Z7: COR | AA7: ITA | AB7: ABR | AC7: CAM | AD7: PGL | AE7: SCN | AF7: VEN | AG7: ARO | AH7: ROM | AJ7: ITA
A8: Grapheme | B8: C | C8: c | D8: c | E8: c | F8: c | G8: c | H8: c | I8: c | J8: c | K8: c | L8: c | M8: c | N8: c | O8: c | P8: c | Q8: c | R8: c | S8: c | T8: c | U8: c | V8: c | W8: c | X8: c | Y8: c | Z8: c | AA8: c | AB8: c | AC8: c | AD8: c | AE8: c | AF8: c | AG8: c | AH8: c | AJ8: g
A9: IPA | B9: k | C9: k | D9: k | E9: k | F9: k | G9: k | H9: k | I9: k | J9: k | K9: k | L9: k | M9: k | N9: k | O9: k | P9: k | Q9: k | R9: k | S9: k | T9: k | U9: k | V9: k | W9: k | X9: k | Y9: k | Z9: k | AA9: k | AB9: k | AC9: k | AD9: k | AE9: k | AF9: k | AG9: k | AH9: k | AJ9: ɡ
A10: IPA key | B10: 19 | C10: 19 | D10: 19 | E10: 19 | F10: 19 | G10: 19 | H10: 19 | I10: 19 | J10: 19 | K10: 19 | L10: 19 | M10: 19 | N10: 19 | O10: 19 | P10: 19 | Q10: 19 | R10: 19 | S10: 19 | T10: 19 | U10: 19 | X10: 19 | Y10: 19 | Z10: 19 | AA10: 19 | AB10: 19 | AC10: 19 | AD10: 19 | AE10: 19 | AF10: 19 | AG10: 19 | AH10: 19 | AJ10: 20
A11: Consonantal +/− | B11: + | C11: + | D11: + | E11: + | F11: + | G11: + | H11: + | I11: + | J11: + | K11: + | L11: + | M11: + | N11: + | O11: + | P11: + | Q11: + | R11: + | S11: + | T11: + | U11: + | X11: + | Y11: + | Z11: + | AA11: + | AB11: + | AC11: + | AD11: + | AE11: + | AF11: + | AG11: + | AH11: + | AJ11: +
A12: Voice +/− | B12: − | C12: − | D12: − | E12: − | F12: − | G12: − | H12: − | I12: − | J12: − | K12: − | L12: − | M12: − | N12: − | O12: − | P12: − | Q12: − | R12: − | S12: − | T12: − | U12: − | X12: − | Y12: − | Z12: − | AA12: − | AB12: − | AC12: − | AD12: − | AE12: − | AF12: − | AG12: − | AH12: − | AJ12: +
A13: Sibilant +/− | B13: − | C13: − | D13: − | E13: − | F13: − | G13: − | H13: − | I13: − | J13: − | K13: − | L13: − | M13: − | N13: − | O13: − | P13: − | Q13: − | R13: − | S13: − | T13: − | U13: − | X13: − | Y13: − | Z13: − | AA13: − | AB13: − | AC13: − | AD13: − | AE13: − | AF13: − | AG13: − | AH13: − | AJ13: −
A14: Lateral +/− | B14: − | C14: − | D14: − | E14: − | F14: − | G14: − | H14: − | I14: − | J14: − | K14: − | L14: − | M14: − | N14: − | O14: − | P14: − | Q14: − | R14: − | S14: − | T14: − | U14: − | X14: − | Y14: − | Z14: − | AA14: − | AB14: − | AC14: − | AD14: − | AE14: − | AF14: − | AG14: − | AH14: − | AJ14: −
A15: Place of articulation | B15: K | C15: K | D15: K | E15: K | F15: K | G15: K | H15: K | I15: K | J15: K | K15: K | L15: K | M15: K | N15: K | O15: K | P15: K | Q15: K | R15: K | S15: K | T15: K | U15: K | X15: K | Y15: K | Z15: K | AA15: K | AB15: K | AC15: K | AD15: K | AE15: K | AF15: K | AG15: K | AH15: K | AJ15: K
A16: Place value | B16: -3 | C16: -3 | D16: -3 | E16: -3 | F16: -3 | G16: -3 | H16: -3 | I16: -3 | J16: -3 | K16: -3 | L16: -3 | M16: -3 | N16: -3 | O16: -3 | P16: -3 | Q16: -3 | R16: -3 | S16: -3 | T16: -3 | U16: -3 | X16: -3 | Y16: -3 | Z16: -3 | AA16: -3 | AB16: -3 | AC16: -3 | AD16: -3 | AE16: -3 | AF16: -3 | AG16: -3 | AH16: -3 | AJ16: -3
A17: Manner of articulation | B17: P | C17: P | D17: P | E17: P | F17: P | G17: P | H17: P | I17: P | J17: P | K17: P | L17: P | M17: P | N17: P | O17: P | P17: P | Q17: P | R17: P | S17: P | T17: P | U17: P | X17: P | Y17: P | Z17: P | AA17: P | AB17: P | AC17: P | AD17: P | AE17: P | AF17: P | AG17: P | AH17: P | AJ17: P
A18: Sonority value | B18: 4 | C18: 4 | D18: 4 | E18: 4 | F18: 4 | G18: 4 | H18: 4 | I18: 4 | J18: 4 | K18: 4 | L18: 4 | M18: 4 | N18: 4 | O18: 4 | P18: 4 | Q18: 4 | R18: 4 | S18: 4 | T18: 4 | U18: 4 | X18: 4 | Y18: 4 | Z18: 4 | AA18: 4 | AB18: 4 | AC18: 4 | AD18: 4 | AE18: 4 | AF18: 4 | AG18: 4 | AH18: 4 | AJ18: 4
AA19: 009a | AJ19: 009b
A20: Overview of common sound changes
A21: 009a: k // #_{o,ŭ} | B21: typically /k/
A22: 009b: k / ɡ / #_{o,ŭ} | B22: typically /ɡ/

Sheet 010 C-
A1: A - Consonantism | D1: 1. Initial Position | I1: 1.1 Simple consonants
A3: Number | B3: 10 | F3: Latin Reference Words
A4: Treatment | B4: C- | F4: CŪLU, CŪRA, CŪNA
A5: Environment | B5: #_ū
A7: Languages | B7: LAT | C7: EU POR | D7: BR POR | E7: GAL | F7: ASL | G7: CAS ESP | H7: AND ESP | I7: AMR ESP | J7: ARG | K7: CAT | L7: VAL | M7: BAL | N7: OCC | O7: GAS OCC | P7: EU FRA | Q7: QBC FRA | R7: WAL | S7: ARP | T7: LIG | U7: LMO | V7: RMH | W7: FUR | X7: LOG SRD | Y7: CPN SRD | Z7: COR | AA7: ITA | AB7: ABR | AC7: CAM | AD7: PGL | AE7: SCN | AF7: VEN | AG7: ARO | AH7: ROM
A8: Grapheme | B8: C | C8: c | D8: c | E8: c | F8: c | G8: c | H8: c | I8: c | J8: c | K8: c | L8: c | M8: c | N8: c | O8: c | P8: c | Q8: c | R8: c | S8: c | T8: c | U8: c | V8: tg | W8: c | X8: c | Y8: c | Z8: c | AA8: c | AB8: c | AC8: c | AD8: c | AE8: c | AF8: c | AG8: c | AH8: c
A9: IPA | B9: k | C9: k | D9: k | E9: k | F9: k | G9: k | H9: k | I9: k | J9: k | K9: k | L9: k | M9: k | N9: k | O9: k | P9: k | Q9: k | R9: k | S9: k | T9: k | U9: k | V9: c | W9: k | X9: k | Y9: k | Z9: k | AA9: k | AB9: k | AC9: k | AD9: k | AE9: k | AF9: k | AG9: k | AH9: k
A10: IPA key | B10: 19 | C10: 19 | D10: 19 | E10: 19 | F10: 19 | G10: 19 | H10: 19 | I10: 19 | J10: 19 | K10: 19 | L10: 19 | M10: 19 | N10: 19 | O10: 19 | P10: 19 | Q10: 19 | R10: 19 | S10: 19 | T10: 19 | U10: 19 | V10: 17 | W10: 19 | X10: 19 | Y10: 19 | Z10: 19 | AA10: 19 | AB10: 19 | AC10: 19 | AD10: 19 | AE10: 19 | AF10: 19 | AG10: 19 | AH10: 19
A11: Consonantal +/− | B11: + | C11: + | D11: + | E11: + | F11: + | G11: + | H11: + | I11: + | J11: + | K11: + | L11: + | M11: + | N11: + | O11: + | P11: + | Q11: + | R11: + | S11: + | T11: + | U11: + | V11: + | W11: + | X11: + | Y11: + | Z11: + | AA11: + | AB11: + | AC11: + | AD11: + | AE11: + | AF11: + | AG11: + | AH11: +
A12: Voice +/− | B12: − | C12: − | D12: − | E12: − | F12: − | G12: − | H12: − | I12: − | J12: − | K12: − | L12: − | M12: − | N12: − | O12: − | P12: − | Q12: − | R12: − | S12: − | T12: − | U12: − | V12: − | W12: − | X12: − | Y12: − | Z12: − | AA12: − | AB12: − | AC12: − | AD12: − | AE12: − | AF12: − | AG12: − | AH12: −
A13: Sibilant +/− | B13: − | C13: − | D13: − | E13: − | F13: − | G13: − | H13: − | I13: − | J13: − | K13: − | L13: − | M13: − | N13: − | O13: − | P13: − | Q13: − | R13: − | S13: − | T13: − | U13: − | V13: − | W13: − | X13: − | Y13: − | Z13: − | AA13: − | AB13: − | AC13: − | AD13: − | AE13: − | AF13: − | AG13: − | AH13: −
A14: Lateral +/− | B14: − | C14: − | D14: − | E14: − | F14: − | G14: − | H14: − | I14: − | J14: − | K14: − | L14: − | M14: − | N14: − | O14: − | P14: − | Q14: − | R14: − | S14: − | T14: − | U14: − | V14: − | W14: − | X14: − | Y14: − | Z14: − | AA14: − | AB14: − | AC14: − | AD14: − | AE14: − | AF14: − | AG14: − | AH14: −
A15: Place of articulation | B15: K | C15: K | D15: K | E15: K | F15: K | G15: K | H15: K | I15: K | J15: K | K15: K | L15: K | M15: K | N15: K | O15: K | P15: K | Q15: K | R15: K | S15: K | T15: K | U15: K | V15: Ɉ | W15: K | X15: K | Y15: K | Z15: K | AA15: K | AB15: K | AC15: K | AD15: K | AE15: K | AF15: K | AG15: K | AH15: K
A16: Place value | B16: -3 | C16: -3 | D16: -3 | E16: -3 | F16: -3 | G16: -3 | H16: -3 | I16: -3 | J16: -3 | K16: -3 | L16: -3 | M16: -3 | N16: -3 | O16: -3 | P16: -3 | Q16: -3 | R16: -3 | S16: -3 | T16: -3 | U16: -3 | V16: -2 | W16: -3 | X16: -3 | Y16: -3 | Z16: -3 | AA16: -3 | AB16: -3 | AC16: -3 | AD16: -3 | AE16: -3 | AF16: -3 | AG16: -3 | AH16: -3
A17: Manner of articulation | B17: P | C17: P | D17: P | E17: P | F17: P | G17: P | H17: P | I17: P | J17: P | K17: P | L17: P | M17: P | N17: P | O17: P | P17: P | Q17: P | R17: P | S17: P | T17: P | U17: P | V17: P | W17: P | X17: P | Y17: P | Z17: P | AA17: P | AB17: P | AC17: P | AD17: P | AE17: P | AF17: P | AG17: P | AH17: P
A18: Sonority value | B18: 4 | C18: 4 | D18: 4 | E18: 4 | F18: 4 | G18: 4 | H18: 4 | I18: 4 | J18: 4 | K18: 4 | L18: 4 | M18: 4 | N18: 4 | O18: 4 | P18: 4 | Q18: 4 | R18: 4 | S18: 4 | T18: 4 | U18: 4 | V18: 4 | W18: 4 | X18: 4 | Y18: 4 | Z18: 4 | AA18: 4 | AB18: 4 | AC18: 4 | AD18: 4 | AE18: 4 | AF18: 4 | AG18: 4 | AH18: 4
A20: Overview of common sound changes
A21: k // #_ū | B21: typically /k/

Sheet 011 G-
A1: A - Consonantism | D1: 1. Initial Position | I1: 1.1 Simple consonants
A3: Number | B3: 11 | F3: Latin Reference Words
A4: Treatment | B4: G- | F4: GĔNĔRU, GĔLU, GY̆PSU
A5: Environment | B5: ˈ#_E
A7: Languages | B7: LAT | C7: EU POR | D7: BR POR | E7: GAL | F7: ASL | G7: CAS ESP | H7: AND ESP | I7: AMR ESP | J7: ARG | K7: CAT | L7: VAL | M7: BAL | N7: OCC | O7: GAS OCC | P7: EU FRA | Q7: QBC FRA | R7: WAL | S7: ARP | T7: LIG | U7: LMO | V7: RMH | W7: FUR | X7: LOG SRD | Y7: CPN SRD | Z7: COR | AA7: ITA | AB7: ABR | AC7: CAM | AD7: PGL | AE7: SCN | AF7: VEN | AG7: ARO | AH7: ROM
A8: Grapheme | B8: G | C8: g | D8: g | E8: x | F8: x | G8: y | H8: y | I8: y | J8: ch | K8: g | L8: g | M8: g | N8: g | O8: g | P8: g | Q8: g | R8: dj | S8: g | T8: z | U8: sg | V8: sch | W8: z | X8: g | Y8: g | Z8: ghj | AA8: g | AC8: j | AE8: j | AF8: z/dh | AG8: dz | AH8: g
A9: IPA | B9: ɡ | C9: ʒ | D9: ʒ | E9: ʃ | F9: ʃ | G9: ɟ͡ʝ | H9: ɟ͡ʝ | I9: ɟ͡ʝ | J9: t̠͡ʃ | K9: ʒ | L9: d̠͡ʒ | M9: ʒ | N9: ̠d̠͡ʒ (d͡z̠) | O9: ʒ | P9: ʒ | Q9: ʒ | R9: d̠͡ʒ | S9: d͡z~ð | T9: z (d͡z) | U9: d̠͡ʒ~z | V9: d̠͡ʒ~ʃ | X9: ɡ | Y9: d̠͡ʒ | Z9: ɟ | AA9: d̠͡ʒ | AC9: j | AE9: j | AF9: z̠~ð | AG9: d͡z̪ | AH9: d̠͡ʒ
A10: IPA key | B10: 20 | C10: 57 | D10: 57 | E10: 56 | F10: 56 | G10: 39 | H10: 39 | I10: 39 | J10: 34 | K10: 57 | L10: 35 | M10: 57 | N10: 194 | O10: 57 | P10: 57 | Q10: 57 | R10: 35 | S10: 107 | T10: 111 | U10: 108 | X10: 20 | Y10: 35 | Z10: 18 | AA10: 35 | AC10: 98 | AE10: 98 | AF10: 109 | AG10: 27 | AH10: 35
A11: Consonantal +/− | B11: + | C11: + | D11: + | E11: + | F11: + | G11: + | H11: + | I11: + | J11: + | K11: + | L11: + | M11: + | N11: + | O11: + | P11: + | Q11: + | R11: + | S11: + | T11: + | U11: + | X11: + | Y11: + | Z11: + | AA11: + | AC11: + | AE11: + | AF11: + | AG11: + | AH11: +
A12: Voice +/− | B12: + | C12: + | D12: + | E12: − | F12: − | G12: + | H12: + | I12: + | J12: − | K12: + | L12: + | M12: + | N12: + | O12: + | P12: + | Q12: + | R12: + | S12: + | T12: + | U12: + | X12: + | Y12: + | Z12: + | AA12: + | AC12: + | AE12: + | AF12: − | AG12: + | AH12: +
A13: Sibilant +/− | B13: − | C13: + | D13: + | E13: + | F13: + | G13: − | H13: − | I13: − | J13: + | K13: + | L13: + | M13: + | N13: + | O13: + | P13: + | Q13: + | R13: + | S13: +/− | T13: + | U13: + | X13: − | Y13: + | Z13: − | AA13: + | AC13: − | AE13: − | AF13: +/− | AG13: + | AH13: +
A14: Lateral +/− | B14: − | C14: − | D14: − | E14: − | F14: − | G14: − | H14: − | I14: − | J14: − | K14: − | L14: − | M14: − | N14: − | O14: − | P14: − | Q14: − | R14: − | S14: − | T14: − | U14: − | X14: − | Y14: − | Z14: − | AA14: − | AC14: − | AE14: − | AF14: − | AG14: − | AH14: −
A15: Place of articulation | B15: K | C15: Ɉ | D15: Ɉ | E15: Ɉ | F15: Ɉ | G15: Ɉ | H15: Ɉ | I15: Ɉ | J15: Ɉ | K15: Ɉ | L15: Ɉ | M15: Ɉ | N15: Ɉ (D) | O15: Ɉ | P15: Ɉ | Q15: Ɉ | R15: Ɉ | S15: D | T15: D | U15: Ɉ~D | X15: K | Y15: Ɉ | Z15: Ɉ | AA15: Ɉ | AC15: Ɉ | AE15: Ɉ | AF15: D | AG15: D | AH15: Ɉ
A16: Place value | B16: -3 | C16: -0.5 | D16: -0.5 | E16: -0.5 | F16: -0.5 | G16: -2 | H16: -2 | I16: -2 | J16: -0.5 | K16: -0.5 | L16: -0.5 | M16: -0.5 | N16: =AVERAGE(-0.5,-0.5,0.5) | O16: -0.5 | P16: -0.5 | Q16: -0.5 | R16: -0.5 | S16: =AVERAGE(1,2) | T16: 1 | U16: =AVERAGE(-0.5,1) | X16: -3 | Y16: -0.5 | Z16: -2 | AA16: -0.5 | AC16: -2 | AE16: -2 | AF16: =AVERAGE(0.5,2) | AG16: =4/3 | AH16: -0.5
A17: Manner of articulation | B17: P | C17: F | D17: F | E17: F | F17: F | G17: P͡F | H17: P͡F | I17: P͡F | J17: P͡F | K17: F | L17: P͡F | M17: F | N17: P͡F | O17: F | P17: F | Q17: F | R17: P͡F | S17: P͡F~F | T17: F (P͡F) | U17: P͡F~F | X17: P | Y17: P͡F | Z17: P | AA17: P͡F | AC17: W | AE17: W | AF17: F | AG17: P͡F | AH17: P͡F
A18: Sonority value | B18: 4 | C18: 2 | D18: 2 | E18: 2 | F18: 2 | G18: 3 | H18: 3 | I18: 3 | J18: 3 | K18: 2 | L18: 3 | M18: 2 | N18: 3 | O18: 2 | P18: 2 | Q18: 2 | R18: 3 | S18: =AVERAGE(3,2) | T18: =AVERAGE(2,2,3) | U18: =AVERAGE(3,2) | X18: 4 | Y18: 3 | Z18: 4 | AA18: 3 | AC18: =1/3 | AE18: =1/3 | AF18: 2 | AG18: 3 | AH18: 3
A20: Overview of common sound changes
A21: ɡ / ? / ˈ#_E | B21: typically palatalized to /(d̠͡)ʒ/
B22: /ɟ͡ʝ/ in ESP

Sheet 012 G-
A1: A - Consonantism | D1: 1. Initial Position | I1: 1.1 Simple consonants
A3: Number | B3: 12 | F3: Latin Reference Words
A4: Treatment | B4: G- | F4: GĔLĀRE, GENŬCŬLU, GENĔSTA, GĬNGĪVA
A5: Environment | B5: #_E.ˈ
A7: Languages | B7: LAT | C7: EU POR | D7: BR POR | E7: GAL | F7: ASL | G7: CAS ESP | H7: AND ESP | I7: AMR ESP | J7: ARG | K7: CAT | L7: VAL | M7: BAL | N7: OCC | O7: GAS OCC | P7: EU FRA | Q7: QBC FRA | R7: WAL | S7: ARP | T7: LIG | U7: LMO | V7: RMH | W7: FUR | X7: LOG SRD | Y7: CPN SRD | Z7: COR | AA7: ITA | AB7: ABR | AC7: CAM | AD7: PGL | AE7: SCN | AF7: VEN | AG7: ARO | AH7: ROM
A8: Grapheme | B8: G | C8: g | D8: g | E8: x | F8: x | G8: h/∅ | H8: h/∅ | I8: h/∅ | J8: ch | K8: g | L8: g | M8: g | N8: g | O8: g | P8: g | Q8: g | R8: dj | S8: g | T8: z | U8: sg | V8: sch | W8: z | X8: g | Y8: g | Z8: ghj | AA8: g | AC8: j | AE8: j | AF8: z/dh | AG8: dz | AH8: g
A9: IPA | B9: ɡ | C9: ʒ | D9: ʒ | E9: ʃ | F9: ʃ | G9: ∅ | H9: ∅ | I9: ∅ | J9: t̠͡ʃ | K9: ʒ | L9: d̠͡ʒ | M9: ʒ | N9: ̠d̠͡ʒ (d͡z̠) | O9: ʒ | P9: ʒ | Q9: ʒ | R9: d̠͡ʒ | S9: d͡z~ð | T9: z (d͡z) | U9: d̠͡ʒ~z | X9: ɡ | Y9: d̠͡ʒ | Z9: ɟ | AA9: d̠͡ʒ | AC9: j | AE9: j | AF9: z̠~ð | AG9: d͡z̪ | AH9: d̠͡ʒ
A10: IPA key | B10: 20 | C10: 57 | D10: 57 | E10: 56 | F10: 56 | J10: 34 | K10: 57 | L10: 35 | M10: 57 | N10: 194 | O10: 57 | P10: 57 | Q10: 57 | R10: 35 | S10: 107 | T10: 111 | U10: 108 | X10: 20 | Y10: 35 | Z10: 18 | AA10: 35 | AC10: 98 | AE10: 98 | AF10: 109 | AG10: 27 | AH10: 35
A11: Consonantal +/− | B11: + | C11: + | D11: + | E11: + | F11: + | G11: − | H11: − | I11: − | J11: + | K11: + | L11: + | M11: + | N11: + | O11: + | P11: + | Q11: + | R11: + | S11: + | T11: + | U11: + | X11: + | Y11: + | Z11: + | AA11: + | AC11: + | AE11: + | AF11: + | AG11: + | AH11: +
A12: Voice +/− | B12: + | C12: + | D12: + | E12: − | F12: − | G12: − | H12: − | I12: − | J12: − | K12: + | L12: + | M12: + | N12: + | O12: + | P12: + | Q12: + | R12: + | S12: + | T12: + | U12: + | X12: + | Y12: + | Z12: + | AA12: + | AC12: + | AE12: + | AF12: − | AG12: + | AH12: +
A13: Sibilant +/− | B13: − | C13: + | D13: + | E13: + | F13: + | G13: − | H13: − | I13: − | J13: + | K13: + | L13: + | M13: + | N13: + | O13: + | P13: + | Q13: + | R13: + | S13: +/− | T13: + | U13: + | X13: − | Y13: + | Z13: − | AA13: + | AC13: − | AE13: − | AF13: +/− | AG13: + | AH13: +
A14: Lateral +/− | B14: − | C14: − | D14: − | E14: − | F14: − | G14: − | H14: − | I14: − | J14: − | K14: − | L14: − | M14: − | N14: − | O14: − | P14: − | Q14: − | R14: − | S14: − | T14: − | U14: − | X14: − | Y14: − | Z14: − | AA14: − | AC14: − | AE14: − | AF14: − | AG14: − | AH14: −
A15: Place of articulation | B15: K | C15: Ɉ | D15: Ɉ | E15: Ɉ | F15: Ɉ | G15: Ɉ | H15: Ɉ | I15: Ɉ | J15: Ɉ | K15: Ɉ | L15: Ɉ | M15: Ɉ | N15: Ɉ (D) | O15: Ɉ | P15: Ɉ | Q15: Ɉ | R15: Ɉ | S15: D | T15: D | U15: Ɉ~D | X15: K | Y15: Ɉ | Z15: Ɉ | AA15: Ɉ | AC15: Ɉ | AE15: Ɉ | AF15: D | AG15: D | AH15: Ɉ
A16: Place value | B16: -3 | C16: -0.5 | D16: -0.5 | E16: -0.5 | F16: -0.5 | G16: -0.5 | H16: -0.5 | I16: -0.5 | J16: -0.5 | K16: -0.5 | L16: -0.5 | M16: -0.5 | N16: =AVERAGE(-0.5,-0.5,0.5) | O16: -0.5 | P16: -0.5 | Q16: -0.5 | R16: -0.5 | S16: =AVERAGE(1,2) | T16: 1 | U16: =AVERAGE(-0.5,1) | X16: -3 | Y16: -0.5 | Z16: -2 | AA16: -0.5 | AC16: -2 | AE16: -2 | AF16: =AVERAGE(0.5,2) | AG16: =4/3 | AH16: -0.5
A17: Manner of articulation | B17: P | C17: F | D17: F | E17: F | F17: F | G17: ∅ | H17: ∅ | I17: ∅ | J17: P͡F | K17: F | L17: P͡F | M17: F | N17: P͡F | O17: F | P17: F | Q17: F | R17: P͡F | S17: P͡F~F | T17: F (P͡F) | U17: P͡F~F | X17: P | Y17: P͡F | Z17: P | AA17: P͡F | AC17: W | AE17: W | AF17: F | AG17: P͡F | AH17: P͡F
A18: Sonority value | B18: 4 | C18: 2 | D18: 2 | E18: 2 | F18: 2 | G18: 0 | H18: 0 | I18: 0 | J18: 3 | K18: 2 | L18: 3 | M18: 2 | N18: 3 | O18: 2 | P18: 2 | Q18: 2 | R18: 3 | S18: =AVERAGE(3,2) | T18: =AVERAGE(2,2,3) | U18: =AVERAGE(3,2) | X18: 4 | Y18: 3 | Z18: 4 | AA18: 3 | AC18: =1/3 | AE18: =1/3 | AF18: 2 | AG18: 3 | AH18: 3
A20: Overview of common sound changes
A21: g / ? / #_E.ˈ | B21: typically palatalized to /(d̠͡)ʒ/
B22: ∅ in ESP

Sheet 013 G-
A1: A - Consonantism | D1: 1. Initial Position | I1: 1.1 Simple consonants
A3: Number | B3: 13 | F3: Latin Reference Words
A4: Treatment | B4: G- | F4: GĂLLU, GĂLLĪNA, GĂLBĬNU, GĂUDĬU, GĂLLA
A5: Environment | B5: #_a
A7: Languages | B7: LAT | C7: EU POR | D7: BR POR | E7: GAL | F7: ASL | G7: CAS ESP | H7: AND ESP | I7: AMR ESP | J7: ARG | K7: CAT | L7: VAL | M7: BAL | N7: OCC | O7: GAS OCC | P7: EU FRA | Q7: QBC FRA | R7: WAL | S7: ARP | T7: LIG | U7: LMO | V7: RMH | W7: FUR | X7: LOG SRD | Y7: CPN SRD | Z7: COR | AA7: ITA | AB7: ABR | AC7: CAM | AD7: PGL | AE7: SCN | AF7: VEN | AG7: ARO | AH7: ROM
A8: Grapheme | B8: G | C8: g | D8: g | E8: g (gh) | F8: g | G8: g | H8: g | I8: g | J8: g | K8: g | L8: g | M8: g | N8: g (j) | O8: g | P8: j/g | Q8: j/g | R8: dj | S8: j | T8: g | U8: g | V8: gi | W8: gj | X8: g | Y8: g | Z8: g | AA8: g | AC8: g | AE8: g/j | AF8: g | AG8: g | AH8: g
A9: IPA | B9: ɡ | C9: ɡ | D9: ɡ | E9: ɡ (ħ) | F9: ɡ | G9: ɡ | H9: ɡ | I9: ɡ | J9: ɡ | K9: ɡ | L9: ɡ | M9: ɡ | N9: ɡ (d͡z) | O9: ɡ | P9: ʒ | Q9: ʒ | R9: d̠͡ʒ | S9: d͡z~ð | T9: ɡ | U9: ɡ | V9: ɟ~d̠͡ʒ | W9: ɟ~d̠͡ʒ | X9: ɡ | Y9: ɡ | Z9: ɡ | AA9: ɡ | AC9: ɡ | AE9: ɡ~j | AF9: ɡ | AG9: ɡ | AH9: ɡ
A10: IPA key | B10: 20 | C10: 20 | D10: 20 | E10: 176 | F10: 20 | G10: 20 | H10: 20 | I10: 20 | J10: 20 | K10: 20 | L10: 20 | M10: 20 | N10: 110 | O10: 20 | P10: 57 | Q10: 57 | R10: 35 | S10: 107 | T10: 20 | U10: 20 | V10: 153 | W10: 153 | X10: 20 | Y10: 20 | Z10: 20 | AA10: 20 | AC10: 20 | AE10: 112 | AF10: 20 | AG10: 20 | AH10: 20
A11: Consonantal +/− | B11: + | C11: + | D11: + | E11: + | F11: + | G11: + | H11: + | I11: + | J11: + | K11: + | L11: + | M11: + | N11: + | O11: + | P11: + | Q11: + | R11: + | S11: + | T11: + | U11: + | V11: + | W11: + | X11: + | Y11: + | Z11: + | AA11: + | AC11: + | AE11: + | AF11: + | AG11: + | AH11: +
A12: Voice +/− | B12: + | C12: + | D12: + | E12: + (−) | F12: + | G12: + | H12: + | I12: + | J12: + | K12: + | L12: + | M12: + | N12: + | O12: + | P12: + | Q12: + | R12: + | S12: + | T12: + | U12: + | V12: + | W12: + | X12: + | Y12: + | Z12: + | AA12: + | AC12: + | AE12: + | AF12: + | AG12: + | AH12: +
A13: Sibilant +/− | B13: − | C13: − | D13: − | E13: − | F13: − | G13: − | H13: − | I13: − | J13: − | K13: − | L13: − | M13: − | N13: −/+ | O13: − | P13: + | Q13: + | R13: + | S13: +/− | T13: − | U13: − | V13: −/+ | W13: −/+ | X13: − | Y13: − | Z13: − | AA13: − | AC13: − | AE13: − | AF13: − | AG13: − | AH13: −
A14: Lateral +/− | B14: − | C14: − | D14: − | E14: − | F14: − | G14: − | H14: − | I14: − | J14: − | K14: − | L14: − | M14: − | N14: − | O14: − | P14: − | Q14: − | R14: − | S14: − | T14: − | U14: − | V14: − | W14: − | X14: − | Y14: − | Z14: − | AA14: − | AC14: − | AE14: − | AF14: − | AG14: − | AH14: −
A15: Place of articulation | B15: K | C15: K | D15: K | E15: K (H) | F15: K | G15: K | H15: K | I15: K | J15: K | K15: K | L15: K | M15: K | N15: K (Ɉ) | O15: K | P15: Ɉ | Q15: Ɉ | R15: Ɉ | S15: D | T15: K | U15: K | V15: Ɉ | W15: Ɉ | X15: K | Y15: K | Z15: K | AA15: K | AC15: K | AE15: K~Ɉ | AF15: K | AG15: K | AH15: K
A16: Place value | B16: -3 | C16: -3 | D16: -3 | E16: =AVERAGE(-3,-3,-5) | F16: -3 | G16: -3 | H16: -3 | I16: -3 | J16: -3 | K16: -3 | L16: -3 | M16: -3 | N16: =AVERAGE(3,3,1) | O16: -3 | P16: -0.5 | Q16: -0.5 | R16: -0.5 | S16: =AVERAGE(1,2) | T16: -3 | U16: -3 | V16: =AVERAGE(-2,-0.5) | W16: =AVERAGE(-2,-0.5) | X16: -3 | Y16: -3 | Z16: -3 | AA16: -3 | AC16: -3 | AE16: =AVERAGE(-3,-2) | AF16: -3 | AG16: -3 | AH16: -3
A17: Manner of articulation | B17: P | C17: P | D17: P | E17: P (F) | F17: P | G17: P | H17: P | I17: P | J17: P | K17: P | L17: P | M17: P | N17: P (P͡F) | O17: P | P17: F | Q17: F | R17: P͡F | S17: P͡F~F | T17: P | U17: P | V17: P~P͡F | W17: P~P͡F | X17: P | Y17: P | Z17: P | AA17: P | AC17: P | AE17: P~W | AF17: P | AG17: P | AH17: P
